<?xml version="1.0"?>
<robot name="4wheels_robot1" xmlns:xacro="http://www.ros.org/wiki/xacro">
        <link name="base_link"/>
       
        <link name="chassis">
            <inertial>
                <origin xyz="0.0 0.0 0.0" rpy="0.0 0.0 0.0"/>
                <mass value="5.0"/>
                <inertia ixx="1.0" ixy="0.0" ixz="0.0" iyy="1.0" iyz="0.0" izz="1.0"/>
            </inertial>
            <visual name="">
                <origin xyz="0.0 0.0 0.15" rpy="0.0 0.0 0.0"/>
                <geometry>
                    <box size="0.6 0.4 0.1"/>
                </geometry>
                <material name="">
                    <color rgba="1.0 1.0 1.0 1.0"/>
                    <texture filename=""/>
                </material>
            </visual>
            <collision>
                <origin xyz="0.0 0.0 0.15" rpy="0.0 0.0 0.0"/>
                <geometry>
                    <box size="0.6 0.4 0.1"/>
                </geometry>
            </collision>
        </link>
        <joint name="joint_name" type="fixed">
            <origin xyz="0.0 0.0 0.0" rpy="0.0 0.0 0.0"/>
            <parent link="base_link"/>
            <child link="chassis"/>
            <limit lower="0.0" upper="0.0" effort="0.0" velocity="0.0"/>
        </joint>

<!-- frist_left_wheel -->
        <link name="frist_left_wheel">
            <inertial>
                <origin xyz="0.0 0.0 0.0" rpy="0.0 0.0 0.0"/>
                <mass value="0.0"/>
                <inertia ixx="1.0" ixy="0.0" ixz="0.0" iyy="1.0" iyz="0.0" izz="1.0"/>
            </inertial>
            <visual name="">
                <origin xyz="0.2 0.4 0.06" rpy="1.5705 0.0 0.0"/>
                <geometry>
                    <cylinder radius="0.1" length="0.05"/>
                </geometry>
                <material name="">
                    <color rgba="1.0 0.0 0.0 1.0"/>
                    <texture filename=""/>
                </material>
            </visual>
            <collision>
                <origin xyz="0.2 0.4 0.06" rpy="1.5705 0.0 0.0"/>
                <geometry>
                    <cylinder radius="0.1" length="0.05"/>
                </geometry>
            </collision>
        </link>
        <joint name="first_left_wheel_joint" type="continuous">
            <origin xyz="0.0 -0.2 0.03" rpy="0.0 0.0 0.0"/>
            <parent link="chassis"/>
            <child link="frist_left_wheel"/>
        </joint>

<!-- frist_right_wheel -->
        <link name="frist_right_wheel">
            <inertial>
                <origin xyz="0.0 0.0 0.0" rpy="0.0 0.0 0.0"/>
                <mass value="0.0"/>
                <inertia ixx="1.0" ixy="0.0" ixz="0.0" iyy="1.0" iyz="0.0" izz="1.0"/>
            </inertial>
            <visual name="">
                <origin xyz="0.2 -0.4 0.06" rpy="1.5705 0.0 0.0"/>
                <geometry>
                    <cylinder radius="0.1" length="0.05"/>
                </geometry>
                <material name="">
                    <color rgba="1.0 0.0 0.0 1.0"/>
                    <texture filename=""/>
                </material>
            </visual>
            <collision>
                <origin xyz="0.2 -0.4 0.06" rpy="1.5705 0.0 0.0"/>
                <geometry>
                    <cylinder radius="0.1" length="0.05"/>
                </geometry>
            </collision>
        </link>
        <joint name="first_right_wheel_joint" type="continuous">
            <origin xyz="0.0 0.2 0.03" rpy="0.0 0.0 0.0"/>
            <parent link="chassis"/>
            <child link="frist_right_wheel"/>
        </joint>

<!-- second_left_wheel -->
        <link name="second_left_wheel">
            <inertial>
                <origin xyz="0.0 0.0 0.0" rpy="0.0 0.0 0.0"/>
                <mass value="0.0"/>
                <inertia ixx="1.0" ixy="0.0" ixz="0.0" iyy="1.0" iyz="0.0" izz="1.0"/>
            </inertial>
            <visual name="">
                <origin xyz="-0.2 0.4 0.06" rpy="1.5705 0.0 0.0"/>
                <geometry>
                    <cylinder radius="0.1" length="0.05"/>
                </geometry>
                <material name="">
                    <color rgba="1.0 0.0 0.0 1.0"/>
                    <texture filename=""/>
                </material>
            </visual>
            <collision>
                <origin xyz="-0.2 0.4 0.06" rpy="1.5705 0.0 0.0"/>
                <geometry>
                    <cylinder radius="0.1" length="0.05"/>
                </geometry>
            </collision>
        </link>
        <joint name="second_left_wheel_joint" type="continuous">
            <origin xyz="0.0 -0.2 0.03" rpy="0.0 0.0 0.0"/>
            <parent link="chassis"/>
            <child link="second_left_wheel"/>
        </joint>

 <!-- second_right_wheel -->
        <link name="second_right_wheel">
            <inertial>
                <origin xyz="0.0 0.0 0.0" rpy="0.0 0.0 0.0"/>
                <mass value="0.0"/>
                <inertia ixx="1.0" ixy="0.0" ixz="0.0" iyy="1.0" iyz="0.0" izz="1.0"/>
            </inertial>
            <visual name="">
                <origin xyz="-0.2 -0.4 0.06" rpy="1.5705 0.0 0.0"/>
                <geometry>
                    <cylinder radius="0.1" length="0.05"/>
                </geometry>
                <material name="">
                    <color rgba="1.0 0.0 0.0 1.0"/>
                    <texture filename=""/>
                </material>
            </visual>
            <collision>
                <origin xyz="-0.2 -0.4 0.06" rpy="1.5705 0.0 0.0"/>
                <geometry>
                    <cylinder radius="0.1" length="0.05"/>
                </geometry>
            </collision>
        </link>
        <joint name="second_right_wheel_joint" type="continuous">
            <origin xyz="0.0 0.2 0.03" rpy="0.0 0.0 0.0"/>
            <parent link="chassis"/>
            <child link="second_right_wheel"/>
        </joint>  

<!-- Attached Lider-->
       <link name="lider_link">
        <inertial>
            <origin xyz="0.0 0.0 0.0" rpy="0.0 0.0 0.0"/>
            <mass value="0.0"/>
            <inertia ixx="1.0" ixy="0.0" ixz="0.0" iyy="1.0" iyz="0.0" izz="1.0"/>
        </inertial>
        <visual name="">
            <origin xyz="0.13 0.0 0.23" rpy="0.0 0.0 0.0"/>
            <geometry>
                <cylinder radius="0.06" length="0.08"/>
            </geometry>
            <material name="">
                <color rgba="1.0 0.0 0.0 1.0"/>
                <texture filename=""/>
            </material>
        </visual>
        <collision>
            <origin xyz="0.13 0.0 0.23" rpy="0.0 0.0 0.0"/>
            <geometry>
                <cylinder radius="0.1" length="0.1"/>
            </geometry>
        </collision>
       </link>
       <joint name="lider_joint" type="fixed">
        <origin xyz="0.0 0.0 0.0" rpy="0.0 0.0 0.0"/>
        <parent link="chassis"/>
        <child link="lider_link"/>
       </joint>    

 <!-- lider specifications -->
  <gazebo reference="lider_specifications">
    <sensor type="ray" name="head_hokuyo_sensor">
      <pose>0 0 0 0 0 0</pose>
      <visualize>true</visualize>
      <update_rate>10</update_rate>
      <ray>
        <scan>
          <horizontal>
            <samples>720</samples>
            <resolution>1</resolution>
            <min_angle>-1.74533</min_angle>
            <max_angle>1.74533</max_angle>
          </horizontal>
        </scan>
        <range>
          <min>0.1</min>
          <max>20.0</max>
          <resolution>0.01</resolution>
        </range>
        <noise>
          <type>gaussian</type>
          <!-- Noise parameters based on published spec for Hokuyo laser
               achieving "+-30mm" accuracy at range < 10m.  A mean of 0.0m and
               stddev of 0.01m will put 99.7% of samples within 0.03m of the true
               reading. -->
          <mean>0.0</mean>
          <stddev>0.01</stddev>
        </noise>
      </ray>
      <plugin name="gazebo_ros_head_hokuyo_controller" filename="libgazebo_ros_gpu_laser.so">
        <topicName>scan</topicName>
        <frameName>lider_link</frameName>
      </plugin>
    </sensor>
  </gazebo>

</robot>